Traceback (most recent call last):
  File "/vscmnt/brussel_pixiu_data/_data_brussel/vo/000/bvo00012/vsc11137/source2suffering/main.py", line 725, in <module>
    exec(exe_plots)
  File "<string>", line 67, in <module>
  File "/data/brussel/vo/000/bvo00012/vsc11137/source2suffering/figures/thiery_2021/plot_ms_and_si.py", line 49, in <module>
    import imageio
ModuleNotFoundError: No module named 'imageio'
